from datetime import datetime, timedelta
from typing import Optional
from jose import JWTError, jwt
from passlib.context import CryptContext
from fastapi import Depends, HTTPException, status
from fastapi.security import OAuth2PasswordBearer
from sqlalchemy.orm import Session

from .config import settings
from .database import get_db
from ..models.user import User

pwd_context = CryptContext(schemes=["bcrypt"], deprecated="auto")
oauth2_scheme = OAuth2PasswordBearer(tokenUrl="api/v1/auth/login")

def verify_password(plain_password: str, hashed_password: str) -> bool:
    return pwd_context.verify(plain_password, hashed_password)

def get_password_hash(password: str) -> str:
    return pwd_context.hash(password)

def create_access_token(data: dict) -> str:
    to_encode = data.copy()
    expire = datetime.utcnow() + timedelta(minutes=settings.ACCESS_TOKEN_EXPIRE_MINUTES)
    to_encode.update({"exp": expire})
    encoded_jwt = jwt.encode(
        to_encode,
        settings.SECRET_KEY,
        algorithm=settings.ALGORITHM
    )
    return encoded_jwt

def authenticate_user(db: Session, email: str, password: str) -> Optional[User]:
    user = db.query(User).filter(User.email == email).first()
    if not user or not verify_password(password, user.hashed_password):
        return None
    return user

async def get_current_user(
    token: str = Depends(oauth2_scheme),
    db: Session = Depends(get_db)
) -> User:
    credentials_exception = HTTPException(
        status_code=status.HTTP_401_UNAUTHORIZED,
        detail="Could not validate credentials",
        headers={"WWW-Authenticate": "Bearer"},
    )
    try:
        payload = jwt.decode(
            token,
            settings.SECRET_KEY,
            algorithms=[settings.ALGORITHM]
        )
        email: str = payload.get("sub")
        if email is None:
            raise credentials_exception
    except JWTError:
        raise credentials_exception
        
    user = db.query(User).filter(User.email == email).first()
    if user is None:
        raise credentials_exception
    return user